Workbook

Sheet Read Me
B2: Metro Detroit Lead Gen System — Low-Voltage / Structured Cabling
B3: Built Aug 2026 · adaptive scoring, refreshed weekly, self-updating as you log outcomes
B5: How this workbook works
B6: • Pipeline tab is the CRM you work from daily — every company you contact gets one row.
B7: • Yellow cells = you fill in (Contact Name, Email, Last Contact Date, Next Action Date — Phone/Website are populated by research when public, but a named contact's direct line/email is usually gatekept, so you'll typically get those on the first call). Blue cells = judgment calls set once when a lead is added (Base Fit, Service Match, Likely Service Need, Evidence). Green cells = live formulas that recalculate the instant you change a Status — no waiting for the weekly refresh.
B8: • Service Match tags each lead against your actual work types (Fiber, Copper/Structured Cabling, Decommissions, Network Setup, Security Camera & Access Control, Cloud/IT Support) so you can tell a generically-good-fit lead from one that actually needs what you do.
B9: • Evidence is the specific, cited reason a lead was added — a job posting, a named project, a prequalification portal — not just 'right category, right region.' Most of the original seed list is honestly labeled 'Category match only' — read that as lower-confidence than a lead with a real citation, and treat the discovery call as verification, not a formality.
B10: • Channel Performance tab is the engine: it tracks real win/loss outcomes per channel and turns them into a multiplier + a Confidence label that adjusts every lead's score automatically.
B11: • Weekly Call Rotation tells you which channel to call each day — its weighting is meant to be revisited monthly against Channel Performance, not just left on autopilot forever.
B13: The scoring algorithm, in full
B14: • Lead Score = Base Fit × Channel Multiplier, clipped to 1-10.
B15: • Base Fit (1-10, set once per lead): a weighted blend of Recurring Revenue Potential (35%), Deal Size (25%), Urgency Signal (20%), and Access Ease (20%) — company-level attributes that don't depend on which channel found them.
... B59: • Friday = admin block: register/monitor bid boards, update Pipeline statuses, log the week's contacts so Channel Performance has real data to work with.

Sheet Channel Performance
A1: Channel Performance — Adaptive Scoring Engine
A2: This table drives the Channel Multiplier + Confidence in Pipeline. Orange = editable assumption. Green = live, computed from your logged outcomes. Don't need to touch this tab — just log Status honestly in Pipeline.
A4: Smoothing constant (K) | C4: 5 | D4: Real attempts in a channel before your results start outweighing the starting Prior. Raise it to trust priors longer; lower it to trust your own data sooner. Also the scale for Confidence, below: Evidence Share = Attempts / (Attempts + K).
A6: Channel | B6: Prior Win Rate | C6: Attempts | D6: Won | E6: Lost | F6: Raw Win Rate | G6: Smoothed Win Rate | H6: Multiplier | I6: Evidence Share | J6: Confidence | K6: Source / Rationale
A7: Property Mgmt | B7: 0.12 | C7: =SUMPRODUCT((Pipeline!$C$6:$C$300=A7)*(Pipeline!$P$6:$P$300<>"Not Contacted")*(Pipeline!$P$6:$P$300<>"")) | D7: =COUNTIFS(Pipeline!$C$6:$C$300,A7,Pipeline!$P$6:$P$300,"Won") | E7: =COUNTIFS(Pipeline!$C$6:$C$300,A7,Pipeline!$P$6:$P$300,"Lost") | F7: =IFERROR(D7/C7,0) | G7: =(B7*$C$4+D7)/($C$4+C7) | H7: =ROUND(0.6+0.8*G7,2) | I7: =C7/(C7+$C$4) | J7: =IF(C7=0,"No data — pure prior",IF(I7<0.25,"Low — mostly prior",IF(I7<0.5,"Building — prior still meaningful","High — mostly real data"))) | K7: Cold outbound to a named decision-maker; anchored above generic SDR cold-call benchmark (~9.4%, SalesHive 2026) since it's a targeted local pitch.
A8: CRE Broker | B8: 0.2 | C8: =SUMPRODUCT((Pipeline!$C$6:$C$300=A8)*(Pipeline!$P$6:$P$300<>"Not Contacted")*(Pipeline!$P$6:$P$300<>"")) | D8: =COUNTIFS(Pipeline!$C$6:$C$300,A8,Pipeline!$P$6:$P$300,"Won") | E8: =COUNTIFS(Pipeline!$C$6:$C$300,A8,Pipeline!$P$6:$P$300,"Lost") | F8: =IFERROR(D8/C8,0) | G8: =(B8*$C$4+D8)/($C$4+C8) | H8: =ROUND(0.6+0.8*G8,2) | I8: =C8/(C8+$C$4) | J8: =IF(C8=0,"No data — pure prior",IF(I8<0.25,"Low — mostly prior",IF(I8<0.5,"Building — prior still meaningful","High — mostly real data"))) | K8: You're asking for an introduction, not selling directly — closer to warm-intro range (referral leads ~25-26%, Landbase/SyncGTM 2026).
A9: MSP | B9: 0.15 | C9: =SUMPRODUCT((Pipeline!$C$6:$C$300=A9)*(Pipeline!$P$6:$P$300<>"Not Contacted")*(Pipeline!$P$6:$P$300<>"")) | D9: =COUNTIFS(Pipeline!$C$6:$C$300,A9,Pipeline!$P$6:$P$300,"Won") | E9: =COUNTIFS(Pipeline!$C$6:$C$300,A9,Pipeline!$P$6:$P$300,"Lost") | F9: =IFERROR(D9/C9,0) | G9: =(B9*$C$4+D9)/($C$4+C9) | H9: =ROUND(0.6+0.8*G9,2) | I9: =C9/(C9+$C$4) | J9: =IF(C9=0,"No data — pure prior",IF(I9<0.25,"Low — mostly prior",IF(I9<0.5,"Building — prior still meaningful","High — mostly real data"))) | K9: Cold outbound but a differentiated, relevant pitch (ex-MSP tech) — between cold-call and referral benchmarks.
A10: TI Electrical/GC | B10: 0.12 | C10: =SUMPRODUCT((Pipeline!$C$6:$C$300=A10)*(Pipeline!$P$6:$P$300<>"Not Contacted")*(Pipeline!$P$6:$P$300<>"")) | D10: =COUNTIFS(Pipeline!$C$6:$C$300,A10,Pipeline!$P$6:$P$300,"Won") | E10: =COUNTIFS(Pipeline!$C$6:$C$300,A10,Pipeline!$P$6:$P$300,"Lost") | F10: =IFERROR(D10/C10,0) | G10: =(B10*$C$4+D10)/($C$4+C10) | H10: =ROUND(0.6+0.8*G10,2) | I10: =C10/(C10+$C$4) | J10: =IF(C10=0,"No data — pure prior",IF(I10<0.25,"Low — mostly prior",IF(I10<0.5,"Building — prior still meaningful","High — mostly real data"))) | K10: Cold outbound to a trade contact; treated like Property Mgmt absent better data.
A11: Platform | B11: 0.25 | C11: =SUMPRODUCT((Pipeline!$C$6:$C$300=A11)*(Pipeline!$P$6:$P$300<>"Not Contacted")*(Pipeline!$P$6:$P$300<>"")) | D11: =COUNTIFS(Pipeline!$C$6:$C$300,A11,Pipeline!$P$6:$P$300,"Won") | E11: =COUNTIFS(Pipeline!$C$6:$C$300,A11,Pipeline!$P$6:$P$300,"Lost") | F11: =IFERROR(D11/C11,0) | G11: =(B11*$C$4+D11)/($C$4+C11) | H11: =ROUND(0.6+0.8*G11,2) | I11: =C11/(C11+$C$4) | J11: =IF(C11=0,"No data — pure prior",IF(I11<0.25,"Low — mostly prior",IF(I11<0.5,"Building — prior still meaningful","High — mostly real data"))) | K11: Self-serve marketplace — 'win' means getting qualified/booked, generally achievable with consistent effort, not a sales rejection scenario.
A12: Bid Board | B12: 0.07 | C12: =SUMPRODUCT((Pipeline!$C$6:$C$300=A12)*(Pipeline!$P$6:$P$300<>"Not Contacted")*(Pipeline!$P$6:$P$300<>"")) | D12: =COUNTIFS(Pipeline!$C$6:$C$300,A12,Pipeline!$P$6:$P$300,"Won") | E12: =COUNTIFS(Pipeline!$C$6:$C$300,A12,Pipeline!$P$6:$P$300,"Lost") | F12: =IFERROR(D12/C12,0) | G12: =(B12*$C$4+D12)/($C$4+C12) | H12: =ROUND(0.6+0.8*G12,2) | I12: =C12/(C12+$C$4) | J12: =IF(C12=0,"No data — pure prior",IF(I12<0.25,"Low — mostly prior",IF(I12<0.5,"Building — prior still meaningful","High — mostly real data"))) | K12: Passive, competitive, anonymous submission — construction leadgen research flags cold list channels as lowest-converting (~9.38% cold call is a ceiling, bid boards are typically worse).
A13: Vendor Program | B13: 0.2 | C13: =SUMPRODUCT((Pipeline!$C$6:$C$300=A13)*(Pipeline!$P$6:$P$300<>"Not Contacted")*(Pipeline!$P$6:$P$300<>"")) | D13: =COUNTIFS(Pipeline!$C$6:$C$300,A13,Pipeline!$P$6:$P$300,"Won") | E13: =COUNTIFS(Pipeline!$C$6:$C$300,A13,Pipeline!$P$6:$P$300,"Lost") | F13: =IFERROR(D13/C13,0) | G13: =(B13*$C$4+D13)/($C$4+C13) | H13: =ROUND(0.6+0.8*G13,2) | I13: =C13/(C13+$C$4) | J13: =IF(C13=0,"No data — pure prior",IF(I13<0.25,"Low — mostly prior",IF(I13<0.5,"Building — prior still meaningful","High — mostly real data"))) | K13: Application-based enrollment against stated criteria — decent odds if criteria are met.
A14: DC Integrator/Staffing | B14: 0.08 | C14: =SUMPRODUCT((Pipeline!$C$6:$C$300=A14)*(Pipeline!$P$6:$P$300<>"Not Contacted")*(Pipeline!$P$6:$P$300<>"")) | D14: =COUNTIFS(Pipeline!$C$6:$C$300,A14,Pipeline!$P$6:$P$300,"Won") | E14: =COUNTIFS(Pipeline!$C$6:$C$300,A14,Pipeline!$P$6:$P$300,"Lost") | F14: =IFERROR(D14/C14,0) | G14: =(B14*$C$4+D14)/($C$4+C14) | H14: =ROUND(0.6+0.8*G14,2) | I14: =C14/(C14+$C$4) | J14: =IF(C14=0,"No data — pure prior",IF(I14<0.25,"Low — mostly prior",IF(I14<0.5,"Building — prior still meaningful","High — mostly real data"))) | K14: Long-game registration into a vetting pipeline for Year 2+ work — low near-term conversion by design.
A15: Association/Networking | B15: 0.22 | C15: =SUMPRODUCT((Pipeline!$C$6:$C$300=A15)*(Pipeline!$P$6:$P$300<>"Not Contacted")*(Pipeline!$P$6:$P$300<>"")) | D15: =COUNTIFS(Pipeline!$C$6:$C$300,A15,Pipeline!$P$6:$P$300,"Won") | E15: =COUNTIFS(Pipeline!$C$6:$C$300,A15,Pipeline!$P$6:$P$300,"Lost") | F15: =IFERROR(D15/C15,0) | G15: =(B15*$C$4+D15)/($C$4+C15) | H15: =ROUND(0.6+0.8*G15,2) | I15: =C15/(C15+$C$4) | J15: =IF(C15=0,"No data — pure prior",IF(I15<0.25,"Low — mostly prior",IF(I15<0.5,"Building — prior still meaningful","High — mostly real data"))) | K15: You're in the room by choice with people who chose to be there too — closer to warm-intro/referral territory than cold outbound (BOMA/IREM events put you directly in front of property/facility managers, your core Tier 1 buyer).

Sheet Dashboard
B2: Pipeline Dashboard
B3: Live counts pulled from the Pipeline tab — update Status there, these move automatically.
B6: By Status | E6: By Tier
B7: Status | C7: Count | E7: Tier | F7: Count
B8: Not Contacted | C8: =COUNTIF(Pipeline!$P$6:$P$300,B8) | E8: 1 | F8: =COUNTIF(Pipeline!$B$6:$B$300,E8)
B9: Contacted | C9: =COUNTIF(Pipeline!$P$6:$P$300,B9) | E9: 2 | F9: =COUNTIF(Pipeline!$B$6:$B$300,E9)
B10: Follow-up Scheduled | C10: =COUNTIF(Pipeline!$P$6:$P$300,B10) | E10: 3 | F10: =COUNTIF(Pipeline!$B$6:$B$300,E10)
B11: Quoted | C11: =COUNTIF(Pipeline!$P$6:$P$300,B11)
B12: Won | C12: =COUNTIF(Pipeline!$P$6:$P$300,B12)
B13: Lost | C13: =COUNTIF(Pipeline!$P$6:$P$300,B13)
B15: Total prospects in pipeline | C15: =COUNTA(Pipeline!$A$6:$A$300)
B17: Calls this week (Last Contact Date in last 7 days) | C17: =SUMPRODUCT((Pipeline!$O$6:$O$300<>"")*(Pipeline!$O$6:$O$300>=TODAY()-7)*(Pipeline!$O$6:$O$300<=TODAY()))
B19: Average Lead Score, open leads (Not Contacted/Contacted) | C19: =IFERROR(SUMPRODUCT(((Pipeline!$P$6:$P$300="Not Contacted")+(Pipeline!$P$6:$P$300="Contacted"))*Pipeline!$G$6:$G$300)/SUMPRODUCT(((Pipeline!$P$6:$P$300="Not Contacted")+(Pipeline!$P$6:$P$300="Contacted"))*1),0)
B21: Top channel right now (by Multiplier) | C21: =INDEX('Channel Performance'!$A$7:$A$15,MATCH(MAX('Channel Performance'!$H$7:$H$15),'Channel Performance'!$H$7:$H$15,0))
B22: See Channel Performance tab for the full breakdown and why.

Sheet Pipeline
A1: Pipeline — Master Prospect Tracker
A2: Log every company you contact here. Yellow = you fill in. Blue = judgment, set once (incl. Service Match against your actual work types). Green = live formula — updates the instant you change Status.
A5: Company | B5: Tier (1/2/3) | C5: Channel | D5: Base Fit (1-10) | E5: Channel Multiplier | F5: Channel Confidence | G5: Lead Score | H5: Service Match | I5: Likely Service Need | J5: Evidence | K5: Contact Name | L5: Phone | M5: Email | N5: Website | O5: Last Contact Date | P5: Status | Q5: Next Action | R5: Next Action Date | S5: Notes
A6: SunByrnes Properties & Construction | B6: 1 | C6: Property Mgmt | D6: 6 | E6: =IFERROR(INDEX('Channel Performance'!$H$7:$H$15,MATCH(C6,'Channel Performance'!$A$7:$A$15,0)),1) | F6: =IFERROR(INDEX('Channel Performance'!$J$7:$J$15,MATCH(C6,'Channel Performance'!$A$7:$A$15,0)),"No data — pure prior") | G6: =ROUND(MIN(10,MAX(1,D6*E6)),1) | H6: Copper/Structured Cabling, Fiber, Decommissions | I6: TI cabling + recurring MACs across office/medical/retail portfolio | J6: Category match only — no specific signal found; worth a discovery call to verify current need. | L6: (586) 997-8500 | N6: sunbyrnes.com | P6: Not Contacted | Q6: Call: intro + capabilities sheet | S6: Rochester Hills. Site notes they vet outside vendors for fit — lead with credentials and COI up front.
A7: PMI Motor City | B7: 1 | C7: Property Mgmt | D7: 6 | E7: =IFERROR(INDEX('Channel Performance'!$H$7:$H$15,MATCH(C7,'Channel Performance'!$A$7:$A$15,0)),1) | F7: =IFERROR(INDEX('Channel Performance'!$J$7:$J$15,MATCH(C7,'Channel Performance'!$A$7:$A$15,0)),"No data — pure prior") | G7: =ROUND(MIN(10,MAX(1,D7*E7)),1) | H7: Copper/Structured Cabling, Decommissions | I7: TI cabling + closet cleanups for office tenant turnover | J7: Category match only — no specific signal found; worth a discovery call to verify current need. | L7: 248-270-5221 | M7: info@pmimotorcity.com | N7: pmimotorcity.com | P7: Not Contacted | Q7: Call: intro + capabilities sheet | S7: Clarkston. Specializes specifically in metro Detroit office buildings — smaller shop, easier to reach a decision-maker.
A8: Farbman Group | B8: 1 | C8: Property Mgmt | D8: 7 | E8: =IFERROR(INDEX('Channel Performance'!$H$7:$H$15,MATCH(C8,'Channel Performance'!$A$7:$A$15,0)),1) | F8: =IFERROR(INDEX('Channel Performance'!$J$7:$J$15,MATCH(C8,'Channel Performance'!$A$7:$A$15,0)),"No data — pure prior") | G8: =ROUND(MIN(10,MAX(1,D8*E8)),1) | H8: Copper/Structured Cabling, Fiber, Decommissions, Network Setup | I8: Recurring MACs + TI cabling at volume across a 25M+ sqft portfolio | J8: Category match only — no specific signal found; worth a discovery call to verify current need. | L8: (248) 353-0500 | N8: farbman.com | P8: Not Contacted | Q8: Call: intro + capabilities sheet | S8: Detroit + Farmington Hills offices. Highest volume potential in this tier; expect more gatekeeping to reach the right facilities contact.
A9: JMZ Management | B9: 1 | C9: Property Mgmt | D9: 5 | E9: =IFERROR(INDEX('Channel Performance'!$H$7:$H$15,MATCH(C9,'Channel Performance'!$A$7:$A$15,0)),1) | F9: =IFERROR(INDEX('Channel Performance'!$J$7:$J$15,MATCH(C9,'Channel Performance'!$A$7:$A$15,0)),"No data — pure prior") | G9: =ROUND(MIN(10,MAX(1,D9*E9)),1) | H9: Copper/Structured Cabling, Decommissions | I9: Office/commercial MACs, smaller deal size per site | J9: Category match only — no specific signal found; worth a discovery call to verify current need. | L9: 248-284-6990 | N9: jmzmanagement.com | P9: Not Contacted | Q9: Call: intro + capabilities sheet | S9: Novi. 1,000+ properties SE Michigan, residential + commercial mix.
A10: Colliers Detroit Office Agency Team | B10: 1 | C10: CRE Broker | D10: 4 | E10: =IFERROR(INDEX('Channel Performance'!$H$7:$H$15,MATCH(C10,'Channel Performance'!$A$7:$A$15,0)),1) | F10: =IFERROR(INDEX('Channel Performance'!$J$7:$J$15,MATCH(C10,'Channel Performance'!$A$7:$A$15,0)),"No data — pure prior") | G10: =ROUND(MIN(10,MAX(1,D10*E10)),1) | H10: Varies — referral only, no direct work type | I10: Referral intel only — not a direct cabling buyer | J10: Category match only — no specific signal found; worth a discovery call to verify current need. | N10: colliers.com | P10: Not Contacted | Q10: Call: ask who's re-tenanting/repositioning | S10: Royal Oak/Birmingham/Ann Arbor. Landlord rep team — knows which buildings are being repositioned before it's public.
A11: CBRE Detroit | B11: 1 | C11: CRE Broker | D11: 6 | E11: =IFERROR(INDEX('Channel Performance'!$H$7:$H$15,MATCH(C11,'Channel Performance'!$A$7:$A$15,0)),1) | F11: =IFERROR(INDEX('Channel Performance'!$J$7:$J$15,MATCH(C11,'Channel Performance'!$A$7:$A$15,0)),"No data — pure prior") | G11: =ROUND(MIN(10,MAX(1,D11*E11)),1) | H11: Copper/Structured Cabling, Fiber, Decommissions | I11: PM division = direct TI/MAC buyer; brokerage side = referral intel | J11: Category match only — no specific signal found; worth a discovery call to verify current need. | N11: cbre.com/offices/corporate/detroit | P11: Not Contacted | Q11: Call: ask who's re-tenanting/repositioning | S11: Southfield office. Dual-purpose contact — ask for both property management and leasing.
A12: JLL Detroit | B12: 1 | C12: CRE Broker | D12: 6 | E12: =IFERROR(INDEX('Channel Performance'!$H$7:$H$15,MATCH(C12,'Channel Performance'!$A$7:$A$15,0)),1) | F12: =IFERROR(INDEX('Channel Performance'!$J$7:$J$15,MATCH(C12,'Channel Performance'!$A$7:$A$15,0)),"No data — pure prior") | G12: =ROUND(MIN(10,MAX(1,D12*E12)),1) | H12: Copper/Structured Cabling, Fiber, Decommissions | I12: PM division = direct TI/MAC buyer; brokerage side = referral intel | J12: Category match only — no specific signal found; worth a discovery call to verify current need. | N12: us.jll.com/en/locations/midwest/detroit | P12: Not Contacted | Q12: Call: ask who's re-tenanting/repositioning | S12: Leasing + property management across metro Detroit.
A13: AdRem Systems Corporation | B13: 1 | C13: MSP | D13: 7 | E13: =IFERROR(INDEX('Channel Performance'!$H$7:$H$15,MATCH(C13,'Channel Performance'!$A$7:$A$15,0)),1) | F13: =IFERROR(INDEX('Channel Performance'!$J$7:$J$15,MATCH(C13,'Channel Performance'!$A$7:$A$15,0)),"No data — pure prior") | G13: =ROUND(MIN(10,MAX(1,D13*E13)),1) | H13: Copper/Structured Cabling, Network Setup, Cloud/IT Support | I13: Cabling subcontract for their client base (network support/outsourcing clients) | J13: Category match only — no specific signal found; worth a discovery call to verify current need. | N13: adrem.com | P13: Not Contacted | Q13: Call: intro, cabling sub for their clients | S13: Detroit-focused MSP, 21 yrs. MSPs are a high-fit channel — they hate pulling cable.
A14: Macro Connect | B14: 1 | C14: MSP | D14: 6 | E14: =IFERROR(INDEX('Channel Performance'!$H$7:$H$15,MATCH(C14,'Channel Performance'!$A$7:$A$15,0)),1) | F14: =IFERROR(INDEX('Channel Performance'!$J$7:$J$15,MATCH(C14,'Channel Performance'!$A$7:$A$15,0)),"No data — pure prior") | G14: =ROUND(MIN(10,MAX(1,D14*E14)),1) | H14: Copper/Structured Cabling, Network Setup, Cloud/IT Support | I14: Cabling subcontract + possible E-Rate school cabling overlap | J14: Category match only — no specific signal found; worth a discovery call to verify current need. | N14: macroconnect.net | P14: Not Contacted | Q14: Call: intro, cabling sub for their clients | S14: Detroit MSP since 1997. Schools + small business focus.
A15: Clutch.co Detroit MSP directory (Realnets, Vista IT Group, Applied Tech, CETech, etc.) | B15: 1 | C15: MSP | D15: 4 | E15: =IFERROR(INDEX('Channel Performance'!$H$7:$H$15,MATCH(C15,'Channel Performance'!$A$7:$A$15,0)),1) | F15: =IFERROR(INDEX('Channel Performance'!$J$7:$J$15,MATCH(C15,'Channel Performance'!$A$7:$A$15,0)),"No data — pure prior") | G15: =ROUND(MIN(10,MAX(1,D15*E15)),1) | H15: Varies by firm — typically Copper/Network Setup/Cloud | I15: Sourcing list, not a single lead — mine for more MSP contacts | J15: Directory itself is real and current (Clutch.co rankings) — but each firm within it is still category-match-only until called. | N15: clutch.co/it-services/msp/detroit | P15: Not Contacted | Q15: Work the list — 10+ more MSPs to call | S15: Ranked directory — use to keep expanding the MSP call list past the two named above.
A16: Pacer Staffing (Pacer Group) | B16: 3 | C16: DC Integrator/Staffing | D16: 5 | E16: =IFERROR(INDEX('Channel Performance'!$H$7:$H$15,MATCH(C16,'Channel Performance'!$A$7:$A$15,0)),1) | F16: =IFERROR(INDEX('Channel Performance'!$J$7:$J$15,MATCH(C16,'Channel Performance'!$A$7:$A$15,0)),"No data — pure prior") | G16: =ROUND(MIN(10,MAX(1,D16*E16)),1) | H16: Fiber, Copper/Structured Cabling, Network Setup | I16: Low-voltage/structured cabling tech roles on hyperscale builds — Year 2+ revenue | J16: Company site explicitly lists 'Low Voltage Technicians' & 'Data Cabling Technician' as staffed role categories — thepacer.com/data-center-staffing-solutions | L16: +1 (215) 666-0012 | M16: Info@pacerstaffing.com | N16: thepacer.com/data-center-staffing-solutions | P16: Not Contacted | Q16: Register as low-voltage/cabling sub for MI projects | S16: National data-center staffing firm, explicitly lists low-voltage techs & cabling specialists. Get on file now for Saline Barn/Lyon Twp/Van Buren buildout.
A17: Walbridge | B17: 3 | C17: DC Integrator/Staffing | D17: 4 | E17: =IFERROR(INDEX('Channel Performance'!$H$7:$H$15,MATCH(C17,'Channel Performance'!$A$7:$A$15,0)),1) | F17: =IFERROR(INDEX('Channel Performance'!$J$7:$J$15,MATCH(C17,'Channel Performance'!$A$7:$A$15,0)),"No data — pure prior") | G17: =ROUND(MIN(10,MAX(1,D17*E17)),1) | H17: Fiber, Copper/Structured Cabling, Network Setup, Decommissions | I17: Future sub/vendor registration for DC low-voltage packages | J17: Confirmed GC of record on the $16B Saline Barn data center project, groundbreaking June 1 2026 — enr.com/articles/63087-record-16b-data-center-project-advances-in-michigan | N17: walbridge.com | P17: Not Contacted | Q17: Find sub/vendor prequalification portal (large GCs commonly use BuildingConnected/TradeTapp — check for one) | S17: Detroit GC running the $16B Saline Barn build. Long-game relationship, not a Year-1 win.
A18: Leviton / CommScope / Panduit / Corning (via ADI rep) | B18: 1 | C18: Vendor Program | D18: 4 | E18: =IFERROR(INDEX('Channel Performance'!$H$7:$H$15,MATCH(C18,'Channel Performance'!$A$7:$A$15,0)),1) | F18: =IFERROR(INDEX('Channel Performance'!$J$7:$J$15,MATCH(C18,'Channel Performance'!$A$7:$A$15,0)),"No data — pure prior") | G18: =ROUND(MIN(10,MAX(1,D18*E18)),1) | H18: Copper/Structured Cabling, Fiber | I18: Certified-installer status unlocks warranty-referral jobs | J18: Category match only — no specific signal found; worth a discovery call to verify current need. | P18: Not Contacted | Q18: Ask ADI rep about certified-installer enrollment | S18: Certified-installer status lets you bid jobs that require a certified installer of record.
A19: Verkada / Ubiquiti dealer programs | B19: 2 | C19: Vendor Program | D19: 4 | E19: =IFERROR(INDEX('Channel Performance'!$H$7:$H$15,MATCH(C19,'Channel Performance'!$A$7:$A$15,0)),1) | F19: =IFERROR(INDEX('Channel Performance'!$J$7:$J$15,MATCH(C19,'Channel Performance'!$A$7:$A$15,0)),"No data — pure prior") | G19: =ROUND(MIN(10,MAX(1,D19*E19)),1) | H19: Security Camera & Access Control, Network Setup | I19: Installer-program referrals for camera/network install jobs | J19: Category match only — no specific signal found; worth a discovery call to verify current need. | P19: Not Contacted | Q19: Apply for installer/dealer program | S19: Camera/network vendors route small install jobs to registered installers in-territory.
A20: Field Nation | B20: 2 | C20: Platform | D20: 6 | E20: =IFERROR(INDEX('Channel Performance'!$H$7:$H$15,MATCH(C20,'Channel Performance'!$A$7:$A$15,0)),1) | F20: =IFERROR(INDEX('Channel Performance'!$J$7:$J$15,MATCH(C20,'Channel Performance'!$A$7:$A$15,0)),"No data — pure prior") | G20: =ROUND(MIN(10,MAX(1,D20*E20)),1) | H20: Copper/Structured Cabling, Fiber, Network Setup, Security Camera & Access Control | I20: Paid calibration jobs; unlocks cabling project visibility once qualified | J20: Platform's own marketing explicitly lists cabling/low-voltage as a served skill category — fieldnation.com/solutions/cabling | N20: fieldnation.com/signup | P20: Not Contacted | Q20: Complete technician signup, list cabling skills | S20: Requires completed work orders in last 3 months in a skill to unlock cabling project visibility — take early low-tier jobs to qualify.
A21: WorkMarket | B21: 2 | C21: Platform | D21: 5 | E21: =IFERROR(INDEX('Channel Performance'!$H$7:$H$15,MATCH(C21,'Channel Performance'!$A$7:$A$15,0)),1) | F21: =IFERROR(INDEX('Channel Performance'!$J$7:$J$15,MATCH(C21,'Channel Performance'!$A$7:$A$15,0)),"No data — pure prior") | G21: =ROUND(MIN(10,MAX(1,D21*E21)),1) | H21: Copper/Structured Cabling, Fiber, Network Setup, Security Camera & Access Control | I21: Second labor marketplace — run in parallel with Field Nation | J21: Category match only — no specific signal found; worth a discovery call to verify current need. | N21: workmarket.com | P21: Not Contacted | Q21: Complete technician signup
A22: The Blue Book Network | B22: 2 | C22: Bid Board | D22: 4 | E22: =IFERROR(INDEX('Channel Performance'!$H$7:$H$15,MATCH(C22,'Channel Performance'!$A$7:$A$15,0)),1) | F22: =IFERROR(INDEX('Channel Performance'!$J$7:$J$15,MATCH(C22,'Channel Performance'!$A$7:$A$15,0)),"No data — pure prior") | G22: =ROUND(MIN(10,MAX(1,D22*E22)),1) | H22: Varies by posted project | I22: Passive lead gen — GCs search this to find subs | J22: Category match only — no specific signal found; worth a discovery call to verify current need. | N22: thebluebook.com | P22: Not Contacted | Q22: Create free contractor listing | S22: Free. One-afternoon task.
A23: PlanHub | B23: 2 | C23: Bid Board | D23: 5 | E23: =IFERROR(INDEX('Channel Performance'!$H$7:$H$15,MATCH(C23,'Channel Performance'!$A$7:$A$15,0)),1) | F23: =IFERROR(INDEX('Channel Performance'!$J$7:$J$15,MATCH(C23,'Channel Performance'!$A$7:$A$15,0)),"No data — pure prior") | G23: =ROUND(MIN(10,MAX(1,D23*E23)),1) | H23: Varies by posted project — electrical/low-voltage packages | I23: Electrical/low-voltage subcontract bid opportunities | J23: Category match only — no specific signal found; worth a discovery call to verify current need. | N23: planhub.com | P23: Not Contacted | Q23: Register, watch for electrical/low-voltage packages | S23: GCs post plans here — more winnable than government bid boards for a new solo op.
A24: ConstructConnect / Dodge | B24: 2 | C24: Bid Board | D24: 4 | E24: =IFERROR(INDEX('Channel Performance'!$H$7:$H$15,MATCH(C24,'Channel Performance'!$A$7:$A$15,0)),1) | F24: =IFERROR(INDEX('Channel Performance'!$J$7:$J$15,MATCH(C24,'Channel Performance'!$A$7:$A$15,0)),"No data — pure prior") | G24: =ROUND(MIN(10,MAX(1,D24*E24)),1) | H24: Varies by posted project | I24: Higher-value bid leads, paid plan room | J24: Category match only — no specific signal found; worth a discovery call to verify current need. | N24: constructconnect.com | P24: Not Contacted | Q24: Evaluate paid plan-room subscription | S24: Worth revisiting once cash flow supports it.
A25: MITN / BidNet (Michigan municipal) | B25: 2 | C25: Bid Board | D25: 3 | E25: =IFERROR(INDEX('Channel Performance'!$H$7:$H$15,MATCH(C25,'Channel Performance'!$A$7:$A$15,0)),1) | F25: =IFERROR(INDEX('Channel Performance'!$J$7:$J$15,MATCH(C25,'Channel Performance'!$A$7:$A$15,0)),"No data — pure prior") | G25: =ROUND(MIN(10,MAX(1,D25*E25)),1) | H25: Copper/Structured Cabling, Fiber, Network Setup | I25: Municipal bids incl. E-Rate school cabling | J25: Category match only — no specific signal found; worth a discovery call to verify current need. | N25: bidnetdirect.com/mitn | P25: Not Contacted | Q25: Register (free) | S25: Hard to win as a brand-new solo op without past performance — register and watch.
A26: SIGMA — State of Michigan vendor registration | B26: 2 | C26: Bid Board | D26: 3 | E26: =IFERROR(INDEX('Channel Performance'!$H$7:$H$15,MATCH(C26,'Channel Performance'!$A$7:$A$15,0)),1) | F26: =IFERROR(INDEX('Channel Performance'!$J$7:$J$15,MATCH(C26,'Channel Performance'!$A$7:$A$15,0)),"No data — pure prior") | G26: =ROUND(MIN(10,MAX(1,D26*E26)),1) | H26: Varies by posted contract | I26: State contract eligibility, long game | J26: Category match only — no specific signal found; worth a discovery call to verify current need. | N26: sigma.michigan.gov | P26: Not Contacted | Q26: Register as vendor | S26: Register and monitor; don't depend on it for Year 1 revenue.
A27: SAM.gov (federal) | B27: 2 | C27: Bid Board | D27: 3 | E27: =IFERROR(INDEX('Channel Performance'!$H$7:$H$15,MATCH(C27,'Channel Performance'!$A$7:$A$15,0)),1) | F27: =IFERROR(INDEX('Channel Performance'!$J$7:$J$15,MATCH(C27,'Channel Performance'!$A$7:$A$15,0)),"No data — pure prior") | G27: =ROUND(MIN(10,MAX(1,D27*E27)),1) | H27: Varies by posted contract | I27: Federal contracting eligibility, Year 2+ channel | J27: Category match only — no specific signal found; worth a discovery call to verify current need. | N27: sam.gov | P27: Not Contacted | Q27: Get UEI number, register | S27: UEI issuance can take time — register early even though this is a long-term play.
A28: J. Simon & Sons Electrical Contractors | B28: 1 | C28: TI Electrical/GC | D28: 6 | E28: =IFERROR(INDEX('Channel Performance'!$H$7:$H$15,MATCH(C28,'Channel Performance'!$A$7:$A$15,0)),1) | F28: =IFERROR(INDEX('Channel Performance'!$J$7:$J$15,MATCH(C28,'Channel Performance'!$A$7:$A$15,0)),"No data — pure prior") | G28: =ROUND(MIN(10,MAX(1,D28*E28)),1) | H28: Copper/Structured Cabling, Network Setup | I28: Sub out low-voltage on their commercial tenant buildout jobs | J28: Site explicitly markets commercial tenant buildout + office property electrical services — jsimonelectric.com/commercial-tenant-buildouts | L28: (248) 399-4640 | N28: jsimonelectric.com | P28: Not Contacted | Q28: Call: intro as low-voltage sub for their TI jobs | S28: Metro Detroit electrical contractor. Real, sourced fill for the TI Electrical/GC channel — this channel had zero named companies before.
A29: Sheker Construction | B29: 1 | C29: TI Electrical/GC | D29: 6 | E29: =IFERROR(INDEX('Channel Performance'!$H$7:$H$15,MATCH(C29,'Channel Performance'!$A$7:$A$15,0)),1) | F29: =IFERROR(INDEX('Channel Performance'!$J$7:$J$15,MATCH(C29,'Channel Performance'!$A$7:$A$15,0)),"No data — pure prior") | G29: =ROUND(MIN(10,MAX(1,D29*E29)),1) | H29: Copper/Structured Cabling, Network Setup, Decommissions | I29: Sub out low-voltage on office build-out/TI projects | J29: Site lists office build-outs as a core industry vertical — shekerconstruction.com/industries/office-build-outs | N29: shekerconstruction.com | P29: Not Contacted | Q29: Call: intro as low-voltage sub for their TI jobs | S29: Oakland County/SE Michigan GC specializing in tenant improvement/build-out.
A30: Metro General Contractors, Inc. | B30: 2 | C30: TI Electrical/GC | D30: 5 | E30: =IFERROR(INDEX('Channel Performance'!$H$7:$H$15,MATCH(C30,'Channel Performance'!$A$7:$A$15,0)),1) | F30: =IFERROR(INDEX('Channel Performance'!$J$7:$J$15,MATCH(C30,'Channel Performance'!$A$7:$A$15,0)),"No data — pure prior") | G30: =ROUND(MIN(10,MAX(1,D30*E30)),1) | H30: Copper/Structured Cabling, Network Setup | I30: Sub out low-voltage on office/commercial buildout projects | J30: Site lists office/tenant improvement buildouts among project types — metrogeneralcontractorsinc.com | L30: (248) 615-1111 | N30: metrogeneralcontractorsinc.com | P30: Not Contacted | Q30: Call: intro as low-voltage sub for their TI jobs | S30: Wixom, MI. Commercial construction buildouts across Michigan.
A31: Barton Malow | B31: 2 | C31: TI Electrical/GC | D31: 5 | E31: =IFERROR(INDEX('Channel Performance'!$H$7:$H$15,MATCH(C31,'Channel Performance'!$A$7:$A$15,0)),1) | F31: =IFERROR(INDEX('Channel Performance'!$J$7:$J$15,MATCH(C31,'Channel Performance'!$A$7:$A$15,0)),"No data — pure prior") | G31: =ROUND(MIN(10,MAX(1,D31*E31)),1) | H31: Copper/Structured Cabling, Fiber, Network Setup, Decommissions | I31: Prequalify as a low-voltage sub for future project packages | J31: Publishes a subcontractor/vendor prequalification process via BuildingConnected — bartonmalow.com/subcontractors | N31: bartonmalow.com/subcontractors | P31: Not Contacted | Q31: Submit sub prequalification via BuildingConnected portal | S31: Southfield, MI. Major GC (founded 1924 in Detroit) — large-project scale, procedural access via prequalification rather than a warm call.
A32: DeMaria Building Company | B32: 2 | C32: TI Electrical/GC | D32: 4 | E32: =IFERROR(INDEX('Channel Performance'!$H$7:$H$15,MATCH(C32,'Channel Performance'!$A$7:$A$15,0)),1) | F32: =IFERROR(INDEX('Channel Performance'!$J$7:$J$15,MATCH(C32,'Channel Performance'!$A$7:$A$15,0)),"No data — pure prior") | G32: =ROUND(MIN(10,MAX(1,D32*E32)),1) | H32: Copper/Structured Cabling, Fiber, Network Setup | I32: Prequalify as a low-voltage sub for future project packages | J32: Active Detroit-area GC with 39+ tracked projects per Levelset's contractor directory — levelset.com/contractors/list/michigan/detroit | P32: Not Contacted | Q32: Find and submit sub prequalification | S32: Detroit-based GC.
A33: BOMA Metro Detroit — Vendor Membership | B33: 1 | C33: Association/Networking | D33: 6 | E33: =IFERROR(INDEX('Channel Performance'!$H$7:$H$15,MATCH(C33,'Channel Performance'!$A$7:$A$15,0)),1) | F33: =IFERROR(INDEX('Channel Performance'!$J$7:$J$15,MATCH(C33,'Channel Performance'!$A$7:$A$15,0)),"No data — pure prior") | G33: =ROUND(MIN(10,MAX(1,D33*E33)),1) | H33: Varies — networking/relationship channel | I33: Vendor membership puts you in front of the property/facility managers who ARE Tier 1 — not one lead, a recurring room full of them | J33: Trade association explicitly for commercial building owners/managers with a vendor membership category; hosts a Trade Fair at Eastern Market plus recurring networking events — bomadet.org/membership, boma.org | L33: 313-483-7702 | M33: info@bomadet.org | N33: bomadet.org | P33: Not Contacted | Q33: Call for vendor membership pricing + ask when the next Trade Fair is | S33: 12900 Hall Road, Suite 180, Sterling Heights, MI 48313. Membership cost not published online — call to get it.
A34: IREM Michigan (Chapter 5) | B34: 1 | C34: Association/Networking | D34: 6 | E34: =IFERROR(INDEX('Channel Performance'!$H$7:$H$15,MATCH(C34,'Channel Performance'!$A$7:$A$15,0)),1) | F34: =IFERROR(INDEX('Channel Performance'!$J$7:$J$15,MATCH(C34,'Channel Performance'!$A$7:$A$15,0)),"No data — pure prior") | G34: =ROUND(MIN(10,MAX(1,D34*E34)),1) | H34: Varies — networking/relationship channel | I34: Membership + events puts you directly in front of real estate/property managers across SE Michigan | J34: Real estate management trade association for SE Michigan; confirmed 9th Annual Sporting Clays Classic Aug 20, 2026 at Bald Mountain, Lake Orion — iremmi5.org | L34: 734-655-0268 | N34: iremmi5.org | P34: Not Contacted | Q34: Call re: membership + register for the Aug 20, 2026 Sporting Clays Classic if timing works | S34: SE Michigan chapter, founded 1939. Time-sensitive: the Sporting Clays event is ~8 days out from when this was added (Aug 12, 2026) — verify date/registration is still open before counting on it.
E35: =IFERROR(INDEX('Channel Performance'!$H$7:$H$15,MATCH(C35,'Channel Performance'!$A$7:$A$15,0)),1) | F35: =IFERROR(INDEX('Channel Performance'!$J$7:$J$15,MATCH(C35,'Channel Performance'!$A$7:$A$15,0)),"No data — pure prior") | G35: =IFERROR(ROUND(MIN(10,MAX(1,D35*E35)),1),"")
E36: =IFERROR(INDEX('Channel Performance'!$H$7:$H$15,MATCH(C36,'Channel Performance'!$A$7:$A$15,0)),1) | F36: =IFERROR(INDEX('Channel Performance'!$J$7:$J$15,MATCH(C36,'Channel Performance'!$A$7:$A$15,0)),"No data — pure prior") | G36: =IFERROR(ROUND(MIN(10,MAX(1,D36*E36)),1),"")
E37: =IFERROR(INDEX('Channel Performance'!$H$7:$H$15,MATCH(C37,'Channel Performance'!$A$7:$A$15,0)),1) | F37: =IFERROR(INDEX('Channel Performance'!$J$7:$J$15,MATCH(C37,'Channel Performance'!$A$7:$A$15,0)),"No data — pure prior") | G37: =IFERROR(ROUND(MIN(10,MAX(1,D37*E37)),1),"")
E38: =IFERROR(INDEX('Channel Performance'!$H$7:$H$15,MATCH(C38,'Channel Performance'!$A$7:$A$15,0)),1) | F38: =IFERROR(INDEX('Channel Performance'!$J$7:$J$15,MATCH(C38,'Channel Performance'!$A$7:$A$15,0)),"No data — pure prior") | G38: =IFERROR(ROUND(MIN(10,MAX(1,D38*E38)),1),"")
E39: =IFERROR(INDEX('Channel Performance'!$H$7:$H$15,MATCH(C39,'Channel Performance'!$A$7:$A$15,0)),1) | F39: =IFERROR(INDEX('Channel Performance'!$J$7:$J$15,MATCH(C39,'Channel Performance'!$A$7:$A$15,0)),"No data — pure prior") | G39: =IFERROR(ROUND(MIN(10,MAX(1,D39*E39)),1),"")
E40: =IFERROR(INDEX('Channel Performance'!$H$7:$H$15,MATCH(C40,'Channel Performance'!$A$7:$A$15,0)),1) | F40: =IFERROR(INDEX('Channel Performance'!$J$7:$J$15,MATCH(C40,'Channel Performance'!$A$7:$A$15,0)),"No data — pure prior") | G40: =IFERROR(ROUND(MIN(10,MAX(1,D40*E40)),1),"")
E41: =IFERROR(INDEX('Channel Performance'!$H$7:$H$15,MATCH(C41,'Channel Performance'!$A$7:$A$15,0)),1) | F41: =IFERROR(INDEX('Channel Performance'!$J$7:$J$15,MATCH(C41,'Channel Performance'!$A$7:$A$15,0)),"No data — pure prior") | G41: =IFERROR(ROUND(MIN(10,MAX(1,D41*E41)),1),"")
E42: =IFERROR(INDEX('Channel Performance'!$H$7:$H$15,MATCH(C42,'Channel Performance'!$A$7:$A$15,0)),1) | F42: =IFERROR(INDEX('Channel Performance'!$J$7:$J$15,MATCH(C42,'Channel Performance'!$A$7:$A$15,0)),"No data — pure prior") | G42: =IFERROR(ROUND(MIN(10,MAX(1,D42*E42)),1),"")
...

Sheet Weekly Call Rotation
A1: Weekly Call Rotation
A2: 10 calls/week minimum. Starting weights below match the Channel Performance priors — revisit monthly against that tab's actual Multipliers as real data accumulates.
A4: Day | B4: Calls | C4: Primary Channel | D4: Secondary / Backup | E4: Why this day
A5: Monday | B5: 3 | C5: Property Managers | D5: CRE Brokers | E5: Start the week on the highest-value recurring channel — TI/MAC work from repositioning buildings.
A6: Tuesday | B6: 3 | C6: MSPs | D6: Vendor Programs | E6: MSPs convert fastest into repeat sub relationships — call while the week is fresh for them too.
A7: Wednesday | B7: 2 | C7: TI Electrical / GC contacts | D7: Property Managers (follow-up) | E7: Electrical contractors sub out low-voltage on the TI jobs the office market is generating right now.
A8: Thursday | B8: 1 | C8: CRE Brokers | D8: Association/Networking (BOMA/IREM) or DC Integrator/Staffing | E8: Brokers for repositioning intel; alternate weeks between chasing BOMA/IREM membership+events (a room full of Tier 1 buyers) and one Tier-3 relationship call to keep the Year 2 data-center pipeline warm.
A9: Friday | B9: 1 | C9: Warmest open follow-up | D9: Admin: bid board registration/monitoring, update Pipeline & Dashboard | E9: Close the loop on anyone warm; keep the system itself current so Channel Performance has real data to work with.
A12: Total | B12: =SUM(B5:B9)
